<?xml version="1.0" encoding="utf-8"?>
<!-- This URDF was automatically created by SolidWorks to URDF Exporter! Originally created by Stephen Brawner (brawner@gmail.com) 
     Commit Version: 1.6.0-1-g15f4949  Build Version: 1.6.7594.29634
     For more information, please see http://wiki.ros.org/sw_urdf_exporter -->
<robot
  name="scara4">
  <link
    name="link1">
    <inertial>
      <origin
        xyz="0.00134256641145745 0.0268120790873557 -0.0397924813753879"
        rpy="0 0 0" />
      <mass
        value="0.333965027627055" />
      <inertia
        ixx="0.00024437961424315"
        ixy="-2.70691571933329E-07"
        ixz="6.65938217240934E-07"
        iyy="0.000362442658167423"
        iyz="3.14489465239985E-07"
        izz="0.000246720965790898" />
    </inertial>
    <visual>
      <origin
        xyz="0 0 0"
        rpy="0 0 0" />
      <geometry>
        <mesh
          filename="package://scara4/meshes/link1.STL" />
      </geometry>
      <material
        name="">
        <color
          rgba="0.752941176470588 0.752941176470588 0.752941176470588 1" />
      </material>
    </visual>
    <collision>
      <origin
        xyz="0 0 0"
        rpy="0 0 0" />
      <geometry>
        <mesh
          filename="package://scara4/meshes/link1.STL" />
      </geometry>
    </collision>
  </link>
  <link
    name="link2">
    <inertial>
      <origin
        xyz="0.000219070401410481 0.082554065645283 0.0156932502112004"
        rpy="0 0 0" />
      <mass
        value="0.341833276422222" />
      <inertia
        ixx="0.000601222703206643"
        ixy="-2.75837561186006E-07"
        ixz="5.92153662104969E-07"
        iyy="0.000316649240889944"
        iyz="-2.03450902493644E-06"
        izz="0.00060053198390385" />
    </inertial>
    <visual>
      <origin
        xyz="0 0 0"
        rpy="0 0 0" />
      <geometry>
        <mesh
          filename="package://scara4/meshes/link2.STL" />
      </geometry>
      <material
        name="">
        <color
          rgba="0.752941176470588 0.752941176470588 0.752941176470588 1" />
      </material>
    </visual>
    <collision>
      <origin
        xyz="0 0 0"
        rpy="0 0 0" />
      <geometry>
        <mesh
          filename="package://scara4/meshes/link2.STL" />
      </geometry>
    </collision>
  </link>
  <joint
    name="joint1"
    type="continuous">
    <origin
      xyz="0 0 0.0408"
      rpy="1.5708 0 3.1416" />
    <parent
      link="link1" />
    <child
      link="link2" />
    <axis
      xyz="0 1 0" />
  </joint>
  <link
    name="link3">
    <inertial>
      <origin
        xyz="-0.000113401252194737 0.0339295858638425 0.0633738369323234"
        rpy="0 0 0" />
      <mass
        value="0.349496704950288" />
      <inertia
        ixx="0.000408165235585055"
        ixy="-5.40308089541596E-07"
        ixz="-1.79850928558629E-06"
        iyy="0.000539133104321668"
        iyz="-8.69432622399406E-06"
        izz="0.000156212046475738" />
    </inertial>
    <visual>
      <origin
        xyz="0 0 0"
        rpy="0 0 0" />
      <geometry>
        <mesh
          filename="package://scara4/meshes/link3.STL" />
      </geometry>
      <material
        name="">
        <color
          rgba="0.752941176470588 0.752941176470588 0.752941176470588 1" />
      </material>
    </visual>
    <collision>
      <origin
        xyz="0 0 0"
        rpy="0 0 0" />
      <geometry>
        <mesh
          filename="package://scara4/meshes/link3.STL" />
      </geometry>
    </collision>
  </link>
  <joint
    name="joint2"
    type="prismatic">
    <origin
      xyz="-4.5017E-05 0.097592 0.017"
      rpy="0 0 0" />
    <parent
      link="link2" />
    <child
      link="link3" />
    <axis
      xyz="0 1 0" />
    <limit
      lower="0"
      upper="0"
      effort="0"
      velocity="0" />
  </joint>
  <link
    name="link4">
    <inertial>
      <origin
        xyz="3.62903793402024E-05 -0.000974279847565318 -0.0572628879918167"
        rpy="0 0 0" />
      <mass
        value="0.132586780122943" />
      <inertia
        ixx="0.000228708978235185"
        ixy="-2.42790930369713E-10"
        ixz="3.85879878036558E-09"
        iyy="0.000238850149148551"
        iyz="9.39543532374007E-06"
        izz="2.12648166568431E-05" />
    </inertial>
    <visual>
      <origin
        xyz="0 0 0"
        rpy="0 0 0" />
      <geometry>
        <mesh
          filename="package://scara4/meshes/link4.STL" />
      </geometry>
      <material
        name="">
        <color
          rgba="0.752941176470588 0.752941176470588 0.752941176470588 1" />
      </material>
    </visual>
    <collision>
      <origin
        xyz="0 0 0"
        rpy="0 0 0" />
      <geometry>
        <mesh
          filename="package://scara4/meshes/link4.STL" />
      </geometry>
    </collision>
  </link>
  <joint
    name="joint3"
    type="continuous">
    <origin
      xyz="4.5017E-05 0 -0.067"
      rpy="0 0 0" />
    <parent
      link="link3" />
    <child
      link="link4" />
    <axis
      xyz="0 1 0" />
  </joint>
  <link
    name="link5">
    <inertial>
      <origin
        xyz="-2.31815511669881E-05 -0.00188155161511602 0.0470091350705414"
        rpy="0 0 0" />
      <mass
        value="0.0592642341472502" />
      <inertia
        ixx="6.54622289057525E-05"
        ixy="-1.36790778528406E-10"
        ixz="-5.80273254623293E-10"
        iyy="6.84736651755936E-05"
        iyz="-1.66089791588376E-06"
        izz="6.61596593344095E-06" />
    </inertial>
    <visual>
      <origin
        xyz="0 0 0"
        rpy="0 0 0" />
      <geometry>
        <mesh
          filename="package://scara4/meshes/link5.STL" />
      </geometry>
      <material
        name="">
        <color
          rgba="0.752941176470588 0.752941176470588 0.752941176470588 1" />
      </material>
    </visual>
    <collision>
      <origin
        xyz="0 0 0"
        rpy="0 0 0" />
      <geometry>
        <mesh
          filename="package://scara4/meshes/link5.STL" />
      </geometry>
    </collision>
  </link>
  <joint
    name="joint4"
    type="continuous">
    <origin
      xyz="0 0 -0.1528"
      rpy="3.1416 0 3.1416" />
    <parent
      link="link4" />
    <child
      link="link5" />
    <axis
      xyz="0 1 0" />
  </joint>
</robot>